[2025-07-21T18:11:37.280+0000] {taskinstance.py:1165} INFO - Dependencies all met for <TaskInstance: trans_dag_26.data_quality_check scheduled__2024-09-03T00:00:00+00:00 [queued]>
[2025-07-21T18:11:37.318+0000] {taskinstance.py:1165} INFO - Dependencies all met for <TaskInstance: trans_dag_26.data_quality_check scheduled__2024-09-03T00:00:00+00:00 [queued]>
[2025-07-21T18:11:37.319+0000] {taskinstance.py:1362} INFO - 
--------------------------------------------------------------------------------
[2025-07-21T18:11:37.321+0000] {taskinstance.py:1363} INFO - Starting attempt 1 of 2
[2025-07-21T18:11:37.324+0000] {taskinstance.py:1364} INFO - 
--------------------------------------------------------------------------------
[2025-07-21T18:11:37.369+0000] {taskinstance.py:1383} INFO - Executing <Task(_PythonDecoratedOperator): data_quality_check> on 2024-09-03 00:00:00+00:00
[2025-07-21T18:11:37.388+0000] {standard_task_runner.py:55} INFO - Started process 79862 to run task
[2025-07-21T18:11:37.405+0000] {standard_task_runner.py:82} INFO - Running: ['***', 'tasks', 'run', 'trans_dag_26', 'data_quality_check', 'scheduled__2024-09-03T00:00:00+00:00', '--job-id', '9946', '--raw', '--subdir', 'DAGS_FOLDER/trans_dag.py', '--cfg-path', '/tmp/tmp8zttwr9_']
[2025-07-21T18:11:37.412+0000] {standard_task_runner.py:83} INFO - Job 9946: Subtask data_quality_check
[2025-07-21T18:11:37.722+0000] {task_command.py:376} INFO - Running <TaskInstance: trans_dag_26.data_quality_check scheduled__2024-09-03T00:00:00+00:00 [running]> on host 77e451e90f2e
[2025-07-21T18:11:38.041+0000] {taskinstance.py:1592} INFO - Exporting the following env vars:
AIRFLOW_CTX_DAG_OWNER=***
AIRFLOW_CTX_DAG_ID=trans_dag_26
AIRFLOW_CTX_TASK_ID=data_quality_check
AIRFLOW_CTX_EXECUTION_DATE=2024-09-03T00:00:00+00:00
AIRFLOW_CTX_TRY_NUMBER=1
AIRFLOW_CTX_DAG_RUN_ID=scheduled__2024-09-03T00:00:00+00:00
[2025-07-21T18:11:38.221+0000] {taskinstance.py:1851} ERROR - Task failed with exception
Traceback (most recent call last):
  File "/home/airflow/.local/lib/python3.7/site-packages/airflow/decorators/base.py", line 188, in execute
    return_value = super().execute(context)
  File "/home/airflow/.local/lib/python3.7/site-packages/airflow/operators/python.py", line 175, in execute
    return_value = self.execute_callable()
  File "/home/airflow/.local/lib/python3.7/site-packages/airflow/operators/python.py", line 193, in execute_callable
    return self.python_callable(*self.op_args, **self.op_kwargs)
  File "/opt/airflow/dags/trans_dag.py", line 64, in data_quality_check
    raise ValueError("Data quality check failed: Null values found in the dataset")
ValueError: Data quality check failed: Null values found in the dataset
[2025-07-21T18:11:38.262+0000] {taskinstance.py:1406} INFO - Marking task as UP_FOR_RETRY. dag_id=trans_dag_26, task_id=data_quality_check, execution_date=20240903T000000, start_date=20250721T181137, end_date=20250721T181138
[2025-07-21T18:11:38.292+0000] {standard_task_runner.py:105} ERROR - Failed to execute job 9946 for task data_quality_check (Data quality check failed: Null values found in the dataset; 79862)
[2025-07-21T18:11:38.323+0000] {local_task_job.py:164} INFO - Task exited with return code 1
[2025-07-21T18:11:38.594+0000] {local_task_job.py:273} INFO - 0 downstream tasks scheduled from follow-on schedule check
