[2025-07-21T17:54:51.428+0000] {taskinstance.py:1165} INFO - Dependencies all met for <TaskInstance: trans_dag_26.data_quality_check scheduled__2024-05-26T00:00:00+00:00 [queued]>
[2025-07-21T17:54:51.454+0000] {taskinstance.py:1165} INFO - Dependencies all met for <TaskInstance: trans_dag_26.data_quality_check scheduled__2024-05-26T00:00:00+00:00 [queued]>
[2025-07-21T17:54:51.459+0000] {taskinstance.py:1362} INFO - 
--------------------------------------------------------------------------------
[2025-07-21T17:54:51.463+0000] {taskinstance.py:1363} INFO - Starting attempt 1 of 2
[2025-07-21T17:54:51.467+0000] {taskinstance.py:1364} INFO - 
--------------------------------------------------------------------------------
[2025-07-21T17:54:51.515+0000] {taskinstance.py:1383} INFO - Executing <Task(_PythonDecoratedOperator): data_quality_check> on 2024-05-26 00:00:00+00:00
[2025-07-21T17:54:51.529+0000] {standard_task_runner.py:55} INFO - Started process 76536 to run task
[2025-07-21T17:54:51.547+0000] {standard_task_runner.py:82} INFO - Running: ['***', 'tasks', 'run', 'trans_dag_26', 'data_quality_check', 'scheduled__2024-05-26T00:00:00+00:00', '--job-id', '9344', '--raw', '--subdir', 'DAGS_FOLDER/trans_dag.py', '--cfg-path', '/tmp/tmpvhgews3u']
[2025-07-21T17:54:51.559+0000] {standard_task_runner.py:83} INFO - Job 9344: Subtask data_quality_check
[2025-07-21T17:54:51.761+0000] {task_command.py:376} INFO - Running <TaskInstance: trans_dag_26.data_quality_check scheduled__2024-05-26T00:00:00+00:00 [running]> on host 77e451e90f2e
[2025-07-21T17:54:51.948+0000] {taskinstance.py:1592} INFO - Exporting the following env vars:
AIRFLOW_CTX_DAG_OWNER=***
AIRFLOW_CTX_DAG_ID=trans_dag_26
AIRFLOW_CTX_TASK_ID=data_quality_check
AIRFLOW_CTX_EXECUTION_DATE=2024-05-26T00:00:00+00:00
AIRFLOW_CTX_TRY_NUMBER=1
AIRFLOW_CTX_DAG_RUN_ID=scheduled__2024-05-26T00:00:00+00:00
[2025-07-21T17:54:52.147+0000] {taskinstance.py:1851} ERROR - Task failed with exception
Traceback (most recent call last):
  File "/home/airflow/.local/lib/python3.7/site-packages/airflow/decorators/base.py", line 188, in execute
    return_value = super().execute(context)
  File "/home/airflow/.local/lib/python3.7/site-packages/airflow/operators/python.py", line 175, in execute
    return_value = self.execute_callable()
  File "/home/airflow/.local/lib/python3.7/site-packages/airflow/operators/python.py", line 193, in execute_callable
    return self.python_callable(*self.op_args, **self.op_kwargs)
  File "/opt/airflow/dags/trans_dag.py", line 64, in data_quality_check
    raise ValueError("Data quality check failed: Null values found in the dataset")
ValueError: Data quality check failed: Null values found in the dataset
[2025-07-21T17:54:52.176+0000] {taskinstance.py:1406} INFO - Marking task as UP_FOR_RETRY. dag_id=trans_dag_26, task_id=data_quality_check, execution_date=20240526T000000, start_date=20250721T175451, end_date=20250721T175452
[2025-07-21T17:54:52.217+0000] {standard_task_runner.py:105} ERROR - Failed to execute job 9344 for task data_quality_check (Data quality check failed: Null values found in the dataset; 76536)
[2025-07-21T17:54:52.245+0000] {local_task_job.py:164} INFO - Task exited with return code 1
[2025-07-21T17:54:52.313+0000] {local_task_job.py:273} INFO - 0 downstream tasks scheduled from follow-on schedule check
