[2025-07-21T17:48:45.446+0000] {taskinstance.py:1165} INFO - Dependencies all met for <TaskInstance: trans_dag_26.data_quality_check scheduled__2024-04-21T00:00:00+00:00 [queued]>
[2025-07-21T17:48:45.486+0000] {taskinstance.py:1165} INFO - Dependencies all met for <TaskInstance: trans_dag_26.data_quality_check scheduled__2024-04-21T00:00:00+00:00 [queued]>
[2025-07-21T17:48:45.489+0000] {taskinstance.py:1362} INFO - 
--------------------------------------------------------------------------------
[2025-07-21T17:48:45.494+0000] {taskinstance.py:1363} INFO - Starting attempt 1 of 2
[2025-07-21T17:48:45.495+0000] {taskinstance.py:1364} INFO - 
--------------------------------------------------------------------------------
[2025-07-21T17:48:45.541+0000] {taskinstance.py:1383} INFO - Executing <Task(_PythonDecoratedOperator): data_quality_check> on 2024-04-21 00:00:00+00:00
[2025-07-21T17:48:45.561+0000] {standard_task_runner.py:55} INFO - Started process 75245 to run task
[2025-07-21T17:48:45.571+0000] {standard_task_runner.py:82} INFO - Running: ['***', 'tasks', 'run', 'trans_dag_26', 'data_quality_check', 'scheduled__2024-04-21T00:00:00+00:00', '--job-id', '9117', '--raw', '--subdir', 'DAGS_FOLDER/trans_dag.py', '--cfg-path', '/tmp/tmppc9onann']
[2025-07-21T17:48:45.577+0000] {standard_task_runner.py:83} INFO - Job 9117: Subtask data_quality_check
[2025-07-21T17:48:45.799+0000] {task_command.py:376} INFO - Running <TaskInstance: trans_dag_26.data_quality_check scheduled__2024-04-21T00:00:00+00:00 [running]> on host 77e451e90f2e
[2025-07-21T17:48:45.995+0000] {taskinstance.py:1592} INFO - Exporting the following env vars:
AIRFLOW_CTX_DAG_OWNER=***
AIRFLOW_CTX_DAG_ID=trans_dag_26
AIRFLOW_CTX_TASK_ID=data_quality_check
AIRFLOW_CTX_EXECUTION_DATE=2024-04-21T00:00:00+00:00
AIRFLOW_CTX_TRY_NUMBER=1
AIRFLOW_CTX_DAG_RUN_ID=scheduled__2024-04-21T00:00:00+00:00
[2025-07-21T17:48:46.004+0000] {taskinstance.py:1851} ERROR - Task failed with exception
Traceback (most recent call last):
  File "/home/airflow/.local/lib/python3.7/site-packages/airflow/decorators/base.py", line 188, in execute
    return_value = super().execute(context)
  File "/home/airflow/.local/lib/python3.7/site-packages/airflow/operators/python.py", line 175, in execute
    return_value = self.execute_callable()
  File "/home/airflow/.local/lib/python3.7/site-packages/airflow/operators/python.py", line 193, in execute_callable
    return self.python_callable(*self.op_args, **self.op_kwargs)
  File "/opt/airflow/dags/trans_dag.py", line 59, in data_quality_check
    df = pd.read_csv(file_path_s3)
  File "/home/airflow/.local/lib/python3.7/site-packages/pandas/util/_decorators.py", line 311, in wrapper
    return func(*args, **kwargs)
  File "/home/airflow/.local/lib/python3.7/site-packages/pandas/io/parsers/readers.py", line 586, in read_csv
    return _read(filepath_or_buffer, kwds)
  File "/home/airflow/.local/lib/python3.7/site-packages/pandas/io/parsers/readers.py", line 482, in _read
    parser = TextFileReader(filepath_or_buffer, **kwds)
  File "/home/airflow/.local/lib/python3.7/site-packages/pandas/io/parsers/readers.py", line 811, in __init__
    self._engine = self._make_engine(self.engine)
  File "/home/airflow/.local/lib/python3.7/site-packages/pandas/io/parsers/readers.py", line 1040, in _make_engine
    return mapping[engine](self.f, **self.options)  # type: ignore[call-arg]
  File "/home/airflow/.local/lib/python3.7/site-packages/pandas/io/parsers/c_parser_wrapper.py", line 69, in __init__
    self._reader = parsers.TextReader(self.handles.handle, **kwds)
  File "pandas/_libs/parsers.pyx", line 549, in pandas._libs.parsers.TextReader.__cinit__
pandas.errors.EmptyDataError: No columns to parse from file
[2025-07-21T17:48:46.034+0000] {taskinstance.py:1406} INFO - Marking task as UP_FOR_RETRY. dag_id=trans_dag_26, task_id=data_quality_check, execution_date=20240421T000000, start_date=20250721T174845, end_date=20250721T174846
[2025-07-21T17:48:46.057+0000] {standard_task_runner.py:105} ERROR - Failed to execute job 9117 for task data_quality_check (No columns to parse from file; 75245)
[2025-07-21T17:48:46.104+0000] {local_task_job.py:164} INFO - Task exited with return code 1
[2025-07-21T17:48:46.149+0000] {local_task_job.py:273} INFO - 0 downstream tasks scheduled from follow-on schedule check
