[2025-07-21T18:14:36.303+0000] {taskinstance.py:1165} INFO - Dependencies all met for <TaskInstance: trans_dag_26.extract scheduled__2024-10-09T00:00:00+00:00 [queued]>
[2025-07-21T18:14:36.317+0000] {taskinstance.py:1165} INFO - Dependencies all met for <TaskInstance: trans_dag_26.extract scheduled__2024-10-09T00:00:00+00:00 [queued]>
[2025-07-21T18:14:36.318+0000] {taskinstance.py:1362} INFO - 
--------------------------------------------------------------------------------
[2025-07-21T18:14:36.319+0000] {taskinstance.py:1363} INFO - Starting attempt 1 of 2
[2025-07-21T18:14:36.320+0000] {taskinstance.py:1364} INFO - 
--------------------------------------------------------------------------------
[2025-07-21T18:14:36.342+0000] {taskinstance.py:1383} INFO - Executing <Task(_PythonDecoratedOperator): extract> on 2024-10-09 00:00:00+00:00
[2025-07-21T18:14:36.354+0000] {standard_task_runner.py:55} INFO - Started process 80820 to run task
[2025-07-21T18:14:36.360+0000] {standard_task_runner.py:82} INFO - Running: ['***', 'tasks', 'run', 'trans_dag_26', 'extract', 'scheduled__2024-10-09T00:00:00+00:00', '--job-id', '10133', '--raw', '--subdir', 'DAGS_FOLDER/trans_dag.py', '--cfg-path', '/tmp/tmp0nllni4o']
[2025-07-21T18:14:36.363+0000] {standard_task_runner.py:83} INFO - Job 10133: Subtask extract
[2025-07-21T18:14:36.501+0000] {task_command.py:376} INFO - Running <TaskInstance: trans_dag_26.extract scheduled__2024-10-09T00:00:00+00:00 [running]> on host 77e451e90f2e
[2025-07-21T18:14:36.610+0000] {taskinstance.py:1592} INFO - Exporting the following env vars:
AIRFLOW_CTX_DAG_OWNER=***
AIRFLOW_CTX_DAG_ID=trans_dag_26
AIRFLOW_CTX_TASK_ID=extract
AIRFLOW_CTX_EXECUTION_DATE=2024-10-09T00:00:00+00:00
AIRFLOW_CTX_TRY_NUMBER=1
AIRFLOW_CTX_DAG_RUN_ID=scheduled__2024-10-09T00:00:00+00:00
[2025-07-21T18:14:36.630+0000] {base.py:71} INFO - Using connection ID 'aws-connect' for task execution.
[2025-07-21T18:14:36.631+0000] {connection_wrapper.py:303} INFO - AWS Connection (conn_id='aws-connect', conn_type='aws') credentials retrieved from login and password.
[2025-07-21T18:15:03.458+0000] {base_job.py:232} ERROR - LocalTaskJob heartbeat got an exception
Traceback (most recent call last):
  File "/home/airflow/.local/lib/python3.7/site-packages/sqlalchemy/engine/base.py", line 3243, in _wrap_pool_connect
    return fn()
  File "/home/airflow/.local/lib/python3.7/site-packages/sqlalchemy/pool/base.py", line 310, in connect
    return _ConnectionFairy._checkout(self)
  File "/home/airflow/.local/lib/python3.7/site-packages/sqlalchemy/pool/base.py", line 868, in _checkout
    fairy = _ConnectionRecord.checkout(pool)
  File "/home/airflow/.local/lib/python3.7/site-packages/sqlalchemy/pool/base.py", line 476, in checkout
    rec = pool._do_get()
  File "/home/airflow/.local/lib/python3.7/site-packages/sqlalchemy/pool/impl.py", line 256, in _do_get
    return self._create_connection()
  File "/home/airflow/.local/lib/python3.7/site-packages/sqlalchemy/pool/base.py", line 256, in _create_connection
    return _ConnectionRecord(self)
  File "/home/airflow/.local/lib/python3.7/site-packages/sqlalchemy/pool/base.py", line 371, in __init__
    self.__connect()
  File "/home/airflow/.local/lib/python3.7/site-packages/sqlalchemy/pool/base.py", line 666, in __connect
    pool.logger.debug("Error on connect(): %s", e)
  File "/home/airflow/.local/lib/python3.7/site-packages/sqlalchemy/util/langhelpers.py", line 72, in __exit__
    with_traceback=exc_tb,
  File "/home/airflow/.local/lib/python3.7/site-packages/sqlalchemy/util/compat.py", line 207, in raise_
    raise exception
  File "/home/airflow/.local/lib/python3.7/site-packages/sqlalchemy/pool/base.py", line 661, in __connect
    self.dbapi_connection = connection = pool._invoke_creator(self)
  File "/home/airflow/.local/lib/python3.7/site-packages/sqlalchemy/engine/create.py", line 590, in connect
    return dialect.connect(*cargs, **cparams)
  File "/home/airflow/.local/lib/python3.7/site-packages/sqlalchemy/engine/default.py", line 584, in connect
    return self.dbapi.connect(*cargs, **cparams)
  File "/home/airflow/.local/lib/python3.7/site-packages/psycopg2/__init__.py", line 122, in connect
    conn = _connect(dsn, connection_factory=connection_factory, **kwasync)
psycopg2.OperationalError: could not translate host name "postgres" to address: Temporary failure in name resolution


The above exception was the direct cause of the following exception:

Traceback (most recent call last):
  File "/home/airflow/.local/lib/python3.7/site-packages/airflow/jobs/base_job.py", line 204, in heartbeat
    session.merge(self)
  File "/home/airflow/.local/lib/python3.7/site-packages/sqlalchemy/orm/session.py", line 2961, in merge
    _resolve_conflict_map=_resolve_conflict_map,
  File "/home/airflow/.local/lib/python3.7/site-packages/sqlalchemy/orm/session.py", line 3039, in _merge
    options=options,
  File "/home/airflow/.local/lib/python3.7/site-packages/sqlalchemy/orm/session.py", line 2775, in get
    identity_token=identity_token,
  File "/home/airflow/.local/lib/python3.7/site-packages/sqlalchemy/orm/session.py", line 2878, in _get_impl
    load_options=load_options,
  File "/home/airflow/.local/lib/python3.7/site-packages/sqlalchemy/orm/loading.py", line 534, in load_on_pk_identity
    bind_arguments=bind_arguments,
  File "/home/airflow/.local/lib/python3.7/site-packages/sqlalchemy/orm/session.py", line 1688, in execute
    conn = self._connection_for_bind(bind)
  File "/home/airflow/.local/lib/python3.7/site-packages/sqlalchemy/orm/session.py", line 1530, in _connection_for_bind
    engine, execution_options
  File "/home/airflow/.local/lib/python3.7/site-packages/sqlalchemy/orm/session.py", line 747, in _connection_for_bind
    conn = bind.connect()
  File "/home/airflow/.local/lib/python3.7/site-packages/sqlalchemy/engine/base.py", line 3197, in connect
    return self._connection_cls(self, close_with_result=close_with_result)
  File "/home/airflow/.local/lib/python3.7/site-packages/sqlalchemy/engine/base.py", line 96, in __init__
    else engine.raw_connection()
  File "/home/airflow/.local/lib/python3.7/site-packages/sqlalchemy/engine/base.py", line 3276, in raw_connection
    return self._wrap_pool_connect(self.pool.connect, _connection)
  File "/home/airflow/.local/lib/python3.7/site-packages/sqlalchemy/engine/base.py", line 3247, in _wrap_pool_connect
    e, dialect, self
  File "/home/airflow/.local/lib/python3.7/site-packages/sqlalchemy/engine/base.py", line 2101, in _handle_dbapi_exception_noconnection
    sqlalchemy_exception, with_traceback=exc_info[2], from_=e
  File "/home/airflow/.local/lib/python3.7/site-packages/sqlalchemy/util/compat.py", line 207, in raise_
    raise exception
  File "/home/airflow/.local/lib/python3.7/site-packages/sqlalchemy/engine/base.py", line 3243, in _wrap_pool_connect
    return fn()
  File "/home/airflow/.local/lib/python3.7/site-packages/sqlalchemy/pool/base.py", line 310, in connect
    return _ConnectionFairy._checkout(self)
  File "/home/airflow/.local/lib/python3.7/site-packages/sqlalchemy/pool/base.py", line 868, in _checkout
    fairy = _ConnectionRecord.checkout(pool)
  File "/home/airflow/.local/lib/python3.7/site-packages/sqlalchemy/pool/base.py", line 476, in checkout
    rec = pool._do_get()
  File "/home/airflow/.local/lib/python3.7/site-packages/sqlalchemy/pool/impl.py", line 256, in _do_get
    return self._create_connection()
  File "/home/airflow/.local/lib/python3.7/site-packages/sqlalchemy/pool/base.py", line 256, in _create_connection
    return _ConnectionRecord(self)
  File "/home/airflow/.local/lib/python3.7/site-packages/sqlalchemy/pool/base.py", line 371, in __init__
    self.__connect()
  File "/home/airflow/.local/lib/python3.7/site-packages/sqlalchemy/pool/base.py", line 666, in __connect
    pool.logger.debug("Error on connect(): %s", e)
  File "/home/airflow/.local/lib/python3.7/site-packages/sqlalchemy/util/langhelpers.py", line 72, in __exit__
    with_traceback=exc_tb,
  File "/home/airflow/.local/lib/python3.7/site-packages/sqlalchemy/util/compat.py", line 207, in raise_
    raise exception
  File "/home/airflow/.local/lib/python3.7/site-packages/sqlalchemy/pool/base.py", line 661, in __connect
    self.dbapi_connection = connection = pool._invoke_creator(self)
  File "/home/airflow/.local/lib/python3.7/site-packages/sqlalchemy/engine/create.py", line 590, in connect
    return dialect.connect(*cargs, **cparams)
  File "/home/airflow/.local/lib/python3.7/site-packages/sqlalchemy/engine/default.py", line 584, in connect
    return self.dbapi.connect(*cargs, **cparams)
  File "/home/airflow/.local/lib/python3.7/site-packages/psycopg2/__init__.py", line 122, in connect
    conn = _connect(dsn, connection_factory=connection_factory, **kwasync)
sqlalchemy.exc.OperationalError: (psycopg2.OperationalError) could not translate host name "postgres" to address: Temporary failure in name resolution

(Background on this error at: https://sqlalche.me/e/14/e3q8)
[2025-07-21T18:15:03.903+0000] {taskinstance.py:1851} ERROR - Task failed with exception
Traceback (most recent call last):
  File "/home/airflow/.local/lib/python3.7/site-packages/aiobotocore/response.py", line 58, in read
    amt if amt is not None else -1
  File "/home/airflow/.local/lib/python3.7/site-packages/aiohttp/streams.py", line 375, in read
    block = await self.readany()
  File "/home/airflow/.local/lib/python3.7/site-packages/aiohttp/streams.py", line 397, in readany
    await self._wait("readany")
  File "/home/airflow/.local/lib/python3.7/site-packages/aiohttp/streams.py", line 304, in _wait
    await waiter
aiohttp.client_exceptions.ServerTimeoutError: Timeout on reading data from socket

During handling of the above exception, another exception occurred:

Traceback (most recent call last):
  File "/home/airflow/.local/lib/python3.7/site-packages/fsspec/asyn.py", line 54, in _runner
    result[0] = await coro
  File "/home/airflow/.local/lib/python3.7/site-packages/s3fs/core.py", line 2298, in _inner_fetch
    return await resp["Body"].read()
  File "/home/airflow/.local/lib/python3.7/site-packages/aiobotocore/response.py", line 62, in read
    endpoint_url=self.__wrapped__.url, error=e
aiobotocore.response.AioReadTimeoutError: Read timeout on endpoint URL: "https://imani-***-data.s3.us-east-2.amazonaws.com/raw/QVI_transaction_data.csv"

The above exception was the direct cause of the following exception:

Traceback (most recent call last):
  File "/home/airflow/.local/lib/python3.7/site-packages/airflow/decorators/base.py", line 188, in execute
    return_value = super().execute(context)
  File "/home/airflow/.local/lib/python3.7/site-packages/airflow/operators/python.py", line 175, in execute
    return_value = self.execute_callable()
  File "/home/airflow/.local/lib/python3.7/site-packages/airflow/operators/python.py", line 193, in execute_callable
    return self.python_callable(*self.op_args, **self.op_kwargs)
  File "/opt/airflow/dags/trans_dag.py", line 34, in extract
    df = pd.read_csv(s3_path, storage_options=storage_options)
  File "/home/airflow/.local/lib/python3.7/site-packages/pandas/util/_decorators.py", line 311, in wrapper
    return func(*args, **kwargs)
  File "/home/airflow/.local/lib/python3.7/site-packages/pandas/io/parsers/readers.py", line 586, in read_csv
    return _read(filepath_or_buffer, kwds)
  File "/home/airflow/.local/lib/python3.7/site-packages/pandas/io/parsers/readers.py", line 482, in _read
    parser = TextFileReader(filepath_or_buffer, **kwds)
  File "/home/airflow/.local/lib/python3.7/site-packages/pandas/io/parsers/readers.py", line 811, in __init__
    self._engine = self._make_engine(self.engine)
  File "/home/airflow/.local/lib/python3.7/site-packages/pandas/io/parsers/readers.py", line 1040, in _make_engine
    return mapping[engine](self.f, **self.options)  # type: ignore[call-arg]
  File "/home/airflow/.local/lib/python3.7/site-packages/pandas/io/parsers/c_parser_wrapper.py", line 69, in __init__
    self._reader = parsers.TextReader(self.handles.handle, **kwds)
  File "pandas/_libs/parsers.pyx", line 542, in pandas._libs.parsers.TextReader.__cinit__
  File "pandas/_libs/parsers.pyx", line 642, in pandas._libs.parsers.TextReader._get_header
  File "pandas/_libs/parsers.pyx", line 843, in pandas._libs.parsers.TextReader._tokenize_rows
  File "pandas/_libs/parsers.pyx", line 1917, in pandas._libs.parsers.raise_parser_error
  File "/home/airflow/.local/lib/python3.7/site-packages/s3fs/core.py", line 2150, in _fetch_range
    req_kw=self.req_kw,
  File "/home/airflow/.local/lib/python3.7/site-packages/s3fs/core.py", line 2286, in _fetch_range
    return sync(fs.loop, _inner_fetch, fs, bucket, key, version_id, start, end, req_kw)
  File "/home/airflow/.local/lib/python3.7/site-packages/fsspec/asyn.py", line 97, in sync
    raise FSTimeoutError from return_result
fsspec.exceptions.FSTimeoutError
[2025-07-21T18:15:14.032+0000] {standard_task_runner.py:105} ERROR - Failed to execute job 10133 for task extract ((psycopg2.OperationalError) could not translate host name "postgres" to address: Temporary failure in name resolution

(Background on this error at: https://sqlalche.me/e/14/e3q8); 80820)
[2025-07-21T18:15:14.174+0000] {local_task_job.py:164} INFO - Task exited with return code 1
[2025-07-21T18:15:14.230+0000] {local_task_job.py:273} INFO - 0 downstream tasks scheduled from follow-on schedule check
