[2025-07-21T17:36:14.586+0000] {taskinstance.py:1165} INFO - Dependencies all met for <TaskInstance: trans_dag_26.data_quality_check scheduled__2024-01-31T00:00:00+00:00 [queued]>
[2025-07-21T17:36:14.620+0000] {taskinstance.py:1165} INFO - Dependencies all met for <TaskInstance: trans_dag_26.data_quality_check scheduled__2024-01-31T00:00:00+00:00 [queued]>
[2025-07-21T17:36:14.622+0000] {taskinstance.py:1362} INFO - 
--------------------------------------------------------------------------------
[2025-07-21T17:36:14.623+0000] {taskinstance.py:1363} INFO - Starting attempt 1 of 2
[2025-07-21T17:36:14.624+0000] {taskinstance.py:1364} INFO - 
--------------------------------------------------------------------------------
[2025-07-21T17:36:14.658+0000] {taskinstance.py:1383} INFO - Executing <Task(_PythonDecoratedOperator): data_quality_check> on 2024-01-31 00:00:00+00:00
[2025-07-21T17:36:14.672+0000] {standard_task_runner.py:55} INFO - Started process 72488 to run task
[2025-07-21T17:36:14.680+0000] {standard_task_runner.py:82} INFO - Running: ['***', 'tasks', 'run', 'trans_dag_26', 'data_quality_check', 'scheduled__2024-01-31T00:00:00+00:00', '--job-id', '8625', '--raw', '--subdir', 'DAGS_FOLDER/trans_dag.py', '--cfg-path', '/tmp/tmpxsymzlm4']
[2025-07-21T17:36:14.686+0000] {standard_task_runner.py:83} INFO - Job 8625: Subtask data_quality_check
[2025-07-21T17:36:14.917+0000] {task_command.py:376} INFO - Running <TaskInstance: trans_dag_26.data_quality_check scheduled__2024-01-31T00:00:00+00:00 [running]> on host 77e451e90f2e
[2025-07-21T17:36:15.158+0000] {taskinstance.py:1592} INFO - Exporting the following env vars:
AIRFLOW_CTX_DAG_OWNER=***
AIRFLOW_CTX_DAG_ID=trans_dag_26
AIRFLOW_CTX_TASK_ID=data_quality_check
AIRFLOW_CTX_EXECUTION_DATE=2024-01-31T00:00:00+00:00
AIRFLOW_CTX_TRY_NUMBER=1
AIRFLOW_CTX_DAG_RUN_ID=scheduled__2024-01-31T00:00:00+00:00
[2025-07-21T17:36:15.325+0000] {taskinstance.py:1851} ERROR - Task failed with exception
Traceback (most recent call last):
  File "/home/airflow/.local/lib/python3.7/site-packages/airflow/decorators/base.py", line 188, in execute
    return_value = super().execute(context)
  File "/home/airflow/.local/lib/python3.7/site-packages/airflow/operators/python.py", line 175, in execute
    return_value = self.execute_callable()
  File "/home/airflow/.local/lib/python3.7/site-packages/airflow/operators/python.py", line 193, in execute_callable
    return self.python_callable(*self.op_args, **self.op_kwargs)
  File "/opt/airflow/dags/trans_dag.py", line 64, in data_quality_check
    raise ValueError("Data quality check failed: Null values found in the dataset")
ValueError: Data quality check failed: Null values found in the dataset
[2025-07-21T17:36:15.375+0000] {taskinstance.py:1406} INFO - Marking task as UP_FOR_RETRY. dag_id=trans_dag_26, task_id=data_quality_check, execution_date=20240131T000000, start_date=20250721T173614, end_date=20250721T173615
[2025-07-21T17:36:15.423+0000] {standard_task_runner.py:105} ERROR - Failed to execute job 8625 for task data_quality_check (Data quality check failed: Null values found in the dataset; 72488)
[2025-07-21T17:36:15.465+0000] {local_task_job.py:164} INFO - Task exited with return code 1
[2025-07-21T17:36:15.549+0000] {local_task_job.py:273} INFO - 0 downstream tasks scheduled from follow-on schedule check
