[2025-07-21T18:32:31.201+0000] {taskinstance.py:1165} INFO - Dependencies all met for <TaskInstance: trans_dag_26.data_quality_check scheduled__2025-01-29T00:00:00+00:00 [queued]>
[2025-07-21T18:32:31.235+0000] {taskinstance.py:1165} INFO - Dependencies all met for <TaskInstance: trans_dag_26.data_quality_check scheduled__2025-01-29T00:00:00+00:00 [queued]>
[2025-07-21T18:32:31.237+0000] {taskinstance.py:1362} INFO - 
--------------------------------------------------------------------------------
[2025-07-21T18:32:31.238+0000] {taskinstance.py:1363} INFO - Starting attempt 1 of 2
[2025-07-21T18:32:31.239+0000] {taskinstance.py:1364} INFO - 
--------------------------------------------------------------------------------
[2025-07-21T18:32:31.298+0000] {taskinstance.py:1383} INFO - Executing <Task(_PythonDecoratedOperator): data_quality_check> on 2025-01-29 00:00:00+00:00
[2025-07-21T18:32:31.322+0000] {standard_task_runner.py:55} INFO - Started process 84904 to run task
[2025-07-21T18:32:31.399+0000] {standard_task_runner.py:82} INFO - Running: ['***', 'tasks', 'run', 'trans_dag_26', 'data_quality_check', 'scheduled__2025-01-29T00:00:00+00:00', '--job-id', '10867', '--raw', '--subdir', 'DAGS_FOLDER/trans_dag.py', '--cfg-path', '/tmp/tmptj6x91om']
[2025-07-21T18:32:31.420+0000] {standard_task_runner.py:83} INFO - Job 10867: Subtask data_quality_check
[2025-07-21T18:32:31.797+0000] {task_command.py:376} INFO - Running <TaskInstance: trans_dag_26.data_quality_check scheduled__2025-01-29T00:00:00+00:00 [running]> on host 77e451e90f2e
[2025-07-21T18:32:32.217+0000] {taskinstance.py:1592} INFO - Exporting the following env vars:
AIRFLOW_CTX_DAG_OWNER=***
AIRFLOW_CTX_DAG_ID=trans_dag_26
AIRFLOW_CTX_TASK_ID=data_quality_check
AIRFLOW_CTX_EXECUTION_DATE=2025-01-29T00:00:00+00:00
AIRFLOW_CTX_TRY_NUMBER=1
AIRFLOW_CTX_DAG_RUN_ID=scheduled__2025-01-29T00:00:00+00:00
[2025-07-21T18:32:32.550+0000] {taskinstance.py:1851} ERROR - Task failed with exception
Traceback (most recent call last):
  File "/home/airflow/.local/lib/python3.7/site-packages/airflow/decorators/base.py", line 188, in execute
    return_value = super().execute(context)
  File "/home/airflow/.local/lib/python3.7/site-packages/airflow/operators/python.py", line 175, in execute
    return_value = self.execute_callable()
  File "/home/airflow/.local/lib/python3.7/site-packages/airflow/operators/python.py", line 193, in execute_callable
    return self.python_callable(*self.op_args, **self.op_kwargs)
  File "/opt/airflow/dags/trans_dag.py", line 64, in data_quality_check
    raise ValueError("Data quality check failed: Null values found in the dataset")
ValueError: Data quality check failed: Null values found in the dataset
[2025-07-21T18:32:32.615+0000] {taskinstance.py:1406} INFO - Marking task as UP_FOR_RETRY. dag_id=trans_dag_26, task_id=data_quality_check, execution_date=20250129T000000, start_date=20250721T183231, end_date=20250721T183232
[2025-07-21T18:32:32.995+0000] {standard_task_runner.py:105} ERROR - Failed to execute job 10867 for task data_quality_check (Data quality check failed: Null values found in the dataset; 84904)
[2025-07-21T18:32:33.084+0000] {local_task_job.py:164} INFO - Task exited with return code 1
[2025-07-21T18:32:33.193+0000] {local_task_job.py:273} INFO - 0 downstream tasks scheduled from follow-on schedule check
