[2025-07-21T18:20:45.364+0000] {taskinstance.py:1165} INFO - Dependencies all met for <TaskInstance: trans_dag_26.upload_to_s3 scheduled__2024-11-07T00:00:00+00:00 [queued]>
[2025-07-21T18:20:45.385+0000] {taskinstance.py:1165} INFO - Dependencies all met for <TaskInstance: trans_dag_26.upload_to_s3 scheduled__2024-11-07T00:00:00+00:00 [queued]>
[2025-07-21T18:20:45.387+0000] {taskinstance.py:1362} INFO - 
--------------------------------------------------------------------------------
[2025-07-21T18:20:45.390+0000] {taskinstance.py:1363} INFO - Starting attempt 1 of 2
[2025-07-21T18:20:45.391+0000] {taskinstance.py:1364} INFO - 
--------------------------------------------------------------------------------
[2025-07-21T18:20:45.415+0000] {taskinstance.py:1383} INFO - Executing <Task(_PythonDecoratedOperator): upload_to_s3> on 2024-11-07 00:00:00+00:00
[2025-07-21T18:20:45.427+0000] {standard_task_runner.py:55} INFO - Started process 82080 to run task
[2025-07-21T18:20:45.434+0000] {standard_task_runner.py:82} INFO - Running: ['***', 'tasks', 'run', 'trans_dag_26', 'upload_to_s3', 'scheduled__2024-11-07T00:00:00+00:00', '--job-id', '10352', '--raw', '--subdir', 'DAGS_FOLDER/trans_dag.py', '--cfg-path', '/tmp/tmpjy779xbv']
[2025-07-21T18:20:45.438+0000] {standard_task_runner.py:83} INFO - Job 10352: Subtask upload_to_s3
[2025-07-21T18:20:45.620+0000] {task_command.py:376} INFO - Running <TaskInstance: trans_dag_26.upload_to_s3 scheduled__2024-11-07T00:00:00+00:00 [running]> on host 77e451e90f2e
[2025-07-21T18:20:45.776+0000] {taskinstance.py:1592} INFO - Exporting the following env vars:
AIRFLOW_CTX_DAG_OWNER=***
AIRFLOW_CTX_DAG_ID=trans_dag_26
AIRFLOW_CTX_TASK_ID=upload_to_s3
AIRFLOW_CTX_EXECUTION_DATE=2024-11-07T00:00:00+00:00
AIRFLOW_CTX_TRY_NUMBER=1
AIRFLOW_CTX_DAG_RUN_ID=scheduled__2024-11-07T00:00:00+00:00
[2025-07-21T18:20:45.794+0000] {base.py:71} INFO - Using connection ID 'aws-connect' for task execution.
[2025-07-21T18:20:45.795+0000] {connection_wrapper.py:303} INFO - AWS Connection (conn_id='aws-connect', conn_type='aws') credentials retrieved from login and password.
[2025-07-21T18:21:36.504+0000] {taskinstance.py:1851} ERROR - Task failed with exception
Traceback (most recent call last):
  File "/home/airflow/.local/lib/python3.7/site-packages/urllib3/connection.py", line 175, in _new_conn
    (self._dns_host, self.port), self.timeout, **extra_kw
  File "/home/airflow/.local/lib/python3.7/site-packages/urllib3/util/connection.py", line 72, in create_connection
    for res in socket.getaddrinfo(host, port, family, socket.SOCK_STREAM):
  File "/usr/local/lib/python3.7/socket.py", line 752, in getaddrinfo
    for res in _socket.getaddrinfo(host, port, family, type, proto, flags):
socket.gaierror: [Errno -3] Temporary failure in name resolution

During handling of the above exception, another exception occurred:

Traceback (most recent call last):
  File "/home/airflow/.local/lib/python3.7/site-packages/botocore/httpsession.py", line 457, in send
    chunked=self._chunked(request.headers),
  File "/home/airflow/.local/lib/python3.7/site-packages/urllib3/connectionpool.py", line 788, in urlopen
    method, url, error=e, _pool=self, _stacktrace=sys.exc_info()[2]
  File "/home/airflow/.local/lib/python3.7/site-packages/urllib3/util/retry.py", line 525, in increment
    raise six.reraise(type(error), error, _stacktrace)
  File "/home/airflow/.local/lib/python3.7/site-packages/urllib3/packages/six.py", line 770, in reraise
    raise value
  File "/home/airflow/.local/lib/python3.7/site-packages/urllib3/connectionpool.py", line 710, in urlopen
    chunked=chunked,
  File "/home/airflow/.local/lib/python3.7/site-packages/urllib3/connectionpool.py", line 386, in _make_request
    self._validate_conn(conn)
  File "/home/airflow/.local/lib/python3.7/site-packages/urllib3/connectionpool.py", line 1042, in _validate_conn
    conn.connect()
  File "/home/airflow/.local/lib/python3.7/site-packages/urllib3/connection.py", line 358, in connect
    self.sock = conn = self._new_conn()
  File "/home/airflow/.local/lib/python3.7/site-packages/urllib3/connection.py", line 187, in _new_conn
    self, "Failed to establish a new connection: %s" % e
urllib3.exceptions.NewConnectionError: <botocore.awsrequest.AWSHTTPSConnection object at 0x7a3232d04090>: Failed to establish a new connection: [Errno -3] Temporary failure in name resolution

During handling of the above exception, another exception occurred:

Traceback (most recent call last):
  File "/home/airflow/.local/lib/python3.7/site-packages/airflow/decorators/base.py", line 188, in execute
    return_value = super().execute(context)
  File "/home/airflow/.local/lib/python3.7/site-packages/airflow/operators/python.py", line 175, in execute
    return_value = self.execute_callable()
  File "/home/airflow/.local/lib/python3.7/site-packages/airflow/operators/python.py", line 193, in execute_callable
    return self.python_callable(*self.op_args, **self.op_kwargs)
  File "/opt/airflow/dags/trans_dag.py", line 89, in upload_to_s3
    s3_hook.load_file(filename=file_path_s3, key=key, bucket_name=bucket_name, replace=True)
  File "/home/airflow/.local/lib/python3.7/site-packages/airflow/providers/amazon/aws/hooks/s3.py", line 64, in wrapper
    return func(*bound_args.args, **bound_args.kwargs)
  File "/home/airflow/.local/lib/python3.7/site-packages/airflow/providers/amazon/aws/hooks/s3.py", line 92, in wrapper
    return func(*bound_args.args, **bound_args.kwargs)
  File "/home/airflow/.local/lib/python3.7/site-packages/airflow/providers/amazon/aws/hooks/s3.py", line 649, in load_file
    client.upload_file(filename, bucket_name, key, ExtraArgs=extra_args, Config=self.transfer_config)
  File "/home/airflow/.local/lib/python3.7/site-packages/boto3/s3/inject.py", line 148, in upload_file
    callback=Callback,
  File "/home/airflow/.local/lib/python3.7/site-packages/boto3/s3/transfer.py", line 288, in upload_file
    future.result()
  File "/home/airflow/.local/lib/python3.7/site-packages/s3transfer/futures.py", line 103, in result
    return self._coordinator.result()
  File "/home/airflow/.local/lib/python3.7/site-packages/s3transfer/futures.py", line 266, in result
    raise self._exception
  File "/home/airflow/.local/lib/python3.7/site-packages/botocore/httpsession.py", line 457, in send
    chunked=self._chunked(request.headers),
  File "/home/airflow/.local/lib/python3.7/site-packages/urllib3/connectionpool.py", line 710, in urlopen
    chunked=chunked,
  File "/home/airflow/.local/lib/python3.7/site-packages/urllib3/connectionpool.py", line 398, in _make_request
    conn.request(method, url, **httplib_request_kw)
  File "/home/airflow/.local/lib/python3.7/site-packages/urllib3/connection.py", line 239, in request
    super(HTTPConnection, self).request(method, url, body=body, headers=headers)
  File "/usr/local/lib/python3.7/http/client.py", line 1281, in request
    self._send_request(method, url, body, headers, encode_chunked)
  File "/home/airflow/.local/lib/python3.7/site-packages/botocore/awsrequest.py", line 95, in _send_request
    method, url, body, headers, *args, **kwargs
  File "/usr/local/lib/python3.7/http/client.py", line 1327, in _send_request
    self.endheaders(body, encode_chunked=encode_chunked)
  File "/usr/local/lib/python3.7/http/client.py", line 1276, in endheaders
    self._send_output(message_body, encode_chunked=encode_chunked)
  File "/home/airflow/.local/lib/python3.7/site-packages/botocore/awsrequest.py", line 130, in _send_output
    self._handle_expect_response(message_body)
  File "/home/airflow/.local/lib/python3.7/site-packages/botocore/awsrequest.py", line 176, in _handle_expect_response
    self._send_message_body(message_body)
  File "/home/airflow/.local/lib/python3.7/site-packages/botocore/awsrequest.py", line 209, in _send_message_body
    self.send(message_body)
  File "/home/airflow/.local/lib/python3.7/site-packages/botocore/awsrequest.py", line 218, in send
    return super().send(str)
  File "/usr/local/lib/python3.7/http/client.py", line 989, in send
    datablock = data.read(self.blocksize)
  File "/home/airflow/.local/lib/python3.7/site-packages/s3transfer/utils.py", line 511, in read
    data = self._fileobj.read(amount_to_read)
  File "/home/airflow/.local/lib/python3.7/site-packages/s3transfer/upload.py", line 90, in read
    raise self._transfer_coordinator.exception
  File "/home/airflow/.local/lib/python3.7/site-packages/botocore/httpsession.py", line 457, in send
    chunked=self._chunked(request.headers),
  File "/home/airflow/.local/lib/python3.7/site-packages/urllib3/connectionpool.py", line 710, in urlopen
    chunked=chunked,
  File "/home/airflow/.local/lib/python3.7/site-packages/urllib3/connectionpool.py", line 398, in _make_request
    conn.request(method, url, **httplib_request_kw)
  File "/home/airflow/.local/lib/python3.7/site-packages/urllib3/connection.py", line 239, in request
    super(HTTPConnection, self).request(method, url, body=body, headers=headers)
  File "/usr/local/lib/python3.7/http/client.py", line 1281, in request
    self._send_request(method, url, body, headers, encode_chunked)
  File "/home/airflow/.local/lib/python3.7/site-packages/botocore/awsrequest.py", line 95, in _send_request
    method, url, body, headers, *args, **kwargs
  File "/usr/local/lib/python3.7/http/client.py", line 1327, in _send_request
    self.endheaders(body, encode_chunked=encode_chunked)
  File "/usr/local/lib/python3.7/http/client.py", line 1276, in endheaders
    self._send_output(message_body, encode_chunked=encode_chunked)
  File "/home/airflow/.local/lib/python3.7/site-packages/botocore/awsrequest.py", line 130, in _send_output
    self._handle_expect_response(message_body)
  File "/home/airflow/.local/lib/python3.7/site-packages/botocore/awsrequest.py", line 176, in _handle_expect_response
    self._send_message_body(message_body)
  File "/home/airflow/.local/lib/python3.7/site-packages/botocore/awsrequest.py", line 209, in _send_message_body
    self.send(message_body)
  File "/home/airflow/.local/lib/python3.7/site-packages/botocore/awsrequest.py", line 218, in send
    return super().send(str)
  File "/usr/local/lib/python3.7/http/client.py", line 989, in send
    datablock = data.read(self.blocksize)
  File "/home/airflow/.local/lib/python3.7/site-packages/s3transfer/utils.py", line 511, in read
    data = self._fileobj.read(amount_to_read)
  File "/home/airflow/.local/lib/python3.7/site-packages/s3transfer/upload.py", line 90, in read
    raise self._transfer_coordinator.exception
  File "/home/airflow/.local/lib/python3.7/site-packages/s3transfer/tasks.py", line 139, in __call__
    return self._execute_main(kwargs)
  File "/home/airflow/.local/lib/python3.7/site-packages/s3transfer/tasks.py", line 162, in _execute_main
    return_value = self._main(**kwargs)
  File "/home/airflow/.local/lib/python3.7/site-packages/s3transfer/upload.py", line 793, in _main
    **extra_args,
  File "/home/airflow/.local/lib/python3.7/site-packages/botocore/client.py", line 508, in _api_call
    return self._make_api_call(operation_name, kwargs)
  File "/home/airflow/.local/lib/python3.7/site-packages/botocore/client.py", line 899, in _make_api_call
    operation_model, request_dict, request_context
  File "/home/airflow/.local/lib/python3.7/site-packages/botocore/client.py", line 921, in _make_request
    return self._endpoint.make_request(operation_model, request_dict)
  File "/home/airflow/.local/lib/python3.7/site-packages/botocore/endpoint.py", line 119, in make_request
    return self._send_request(request_dict, operation_model)
  File "/home/airflow/.local/lib/python3.7/site-packages/botocore/endpoint.py", line 207, in _send_request
    exception,
  File "/home/airflow/.local/lib/python3.7/site-packages/botocore/endpoint.py", line 361, in _needs_retry
    request_dict=request_dict,
  File "/home/airflow/.local/lib/python3.7/site-packages/botocore/hooks.py", line 412, in emit
    return self._emitter.emit(aliased_event_name, **kwargs)
  File "/home/airflow/.local/lib/python3.7/site-packages/botocore/hooks.py", line 256, in emit
    return self._emit(event_name, kwargs)
  File "/home/airflow/.local/lib/python3.7/site-packages/botocore/hooks.py", line 239, in _emit
    response = handler(**kwargs)
  File "/home/airflow/.local/lib/python3.7/site-packages/botocore/retryhandler.py", line 207, in __call__
    if self._checker(**checker_kwargs):
  File "/home/airflow/.local/lib/python3.7/site-packages/botocore/retryhandler.py", line 285, in __call__
    attempt_number, response, caught_exception
  File "/home/airflow/.local/lib/python3.7/site-packages/botocore/retryhandler.py", line 320, in _should_retry
    return self._checker(attempt_number, response, caught_exception)
  File "/home/airflow/.local/lib/python3.7/site-packages/botocore/retryhandler.py", line 364, in __call__
    attempt_number, response, caught_exception
  File "/home/airflow/.local/lib/python3.7/site-packages/botocore/retryhandler.py", line 248, in __call__
    attempt_number, caught_exception
  File "/home/airflow/.local/lib/python3.7/site-packages/botocore/retryhandler.py", line 416, in _check_caught_exception
    raise caught_exception
  File "/home/airflow/.local/lib/python3.7/site-packages/botocore/endpoint.py", line 281, in _do_get_response
    http_response = self._send(request)
  File "/home/airflow/.local/lib/python3.7/site-packages/botocore/endpoint.py", line 377, in _send
    return self.http_session.send(request)
  File "/home/airflow/.local/lib/python3.7/site-packages/botocore/httpsession.py", line 477, in send
    raise EndpointConnectionError(endpoint_url=request.url, error=e)
botocore.exceptions.EndpointConnectionError: Could not connect to the endpoint URL: "https://imani-***-data.s3.us-east-2.amazonaws.com/transformed/transformed.csv?uploadId=79L5sSeVj1UPRxEN0G6CodL9F6IGiVoRa3MP5nYQhji0zOB2IqHWAY14lDJGMcFI_2W4AOI7rurQi.WcVaJ15twyZIogENrC7CmIJuvNm.geql4Y.7edMvySpcxuzwL7&partNumber=3"
[2025-07-21T18:21:36.560+0000] {taskinstance.py:1406} INFO - Marking task as UP_FOR_RETRY. dag_id=trans_dag_26, task_id=upload_to_s3, execution_date=20241107T000000, start_date=20250721T182045, end_date=20250721T182136
[2025-07-21T18:21:36.588+0000] {standard_task_runner.py:105} ERROR - Failed to execute job 10352 for task upload_to_s3 (Could not connect to the endpoint URL: "https://imani-***-data.s3.us-east-2.amazonaws.com/transformed/transformed.csv?uploadId=79L5sSeVj1UPRxEN0G6CodL9F6IGiVoRa3MP5nYQhji0zOB2IqHWAY14lDJGMcFI_2W4AOI7rurQi.WcVaJ15twyZIogENrC7CmIJuvNm.geql4Y.7edMvySpcxuzwL7&partNumber=3"; 82080)
[2025-07-21T18:21:36.623+0000] {local_task_job.py:164} INFO - Task exited with return code 1
[2025-07-21T18:21:36.654+0000] {local_task_job.py:273} INFO - 0 downstream tasks scheduled from follow-on schedule check
