[2025-07-21T18:36:23.434+0000] {taskinstance.py:1165} INFO - Dependencies all met for <TaskInstance: trans_dag_26.extract scheduled__2025-02-22T00:00:00+00:00 [queued]>
[2025-07-21T18:36:23.460+0000] {taskinstance.py:1165} INFO - Dependencies all met for <TaskInstance: trans_dag_26.extract scheduled__2025-02-22T00:00:00+00:00 [queued]>
[2025-07-21T18:36:23.461+0000] {taskinstance.py:1362} INFO - 
--------------------------------------------------------------------------------
[2025-07-21T18:36:23.463+0000] {taskinstance.py:1363} INFO - Starting attempt 2 of 2
[2025-07-21T18:36:23.463+0000] {taskinstance.py:1364} INFO - 
--------------------------------------------------------------------------------
[2025-07-21T18:36:23.494+0000] {taskinstance.py:1383} INFO - Executing <Task(_PythonDecoratedOperator): extract> on 2025-02-22 00:00:00+00:00
[2025-07-21T18:36:23.506+0000] {standard_task_runner.py:55} INFO - Started process 85763 to run task
[2025-07-21T18:36:23.512+0000] {standard_task_runner.py:82} INFO - Running: ['***', 'tasks', 'run', 'trans_dag_26', 'extract', 'scheduled__2025-02-22T00:00:00+00:00', '--job-id', '11029', '--raw', '--subdir', 'DAGS_FOLDER/trans_dag.py', '--cfg-path', '/tmp/tmpmxoqop7g']
[2025-07-21T18:36:23.516+0000] {standard_task_runner.py:83} INFO - Job 11029: Subtask extract
[2025-07-21T18:36:23.769+0000] {task_command.py:376} INFO - Running <TaskInstance: trans_dag_26.extract scheduled__2025-02-22T00:00:00+00:00 [running]> on host 77e451e90f2e
[2025-07-21T18:36:23.939+0000] {taskinstance.py:1592} INFO - Exporting the following env vars:
AIRFLOW_CTX_DAG_OWNER=***
AIRFLOW_CTX_DAG_ID=trans_dag_26
AIRFLOW_CTX_TASK_ID=extract
AIRFLOW_CTX_EXECUTION_DATE=2025-02-22T00:00:00+00:00
AIRFLOW_CTX_TRY_NUMBER=2
AIRFLOW_CTX_DAG_RUN_ID=scheduled__2025-02-22T00:00:00+00:00
[2025-07-21T18:36:23.961+0000] {base.py:71} INFO - Using connection ID 'aws-connect' for task execution.
[2025-07-21T18:36:23.962+0000] {connection_wrapper.py:303} INFO - AWS Connection (conn_id='aws-connect', conn_type='aws') credentials retrieved from login and password.
[2025-07-21T22:10:46.942+0000] {taskinstance.py:1851} ERROR - Task failed with exception
Traceback (most recent call last):
  File "/home/airflow/.local/lib/python3.7/site-packages/s3fs/core.py", line 112, in _error_wrapper
    return await func(*args, **kwargs)
  File "/home/airflow/.local/lib/python3.7/site-packages/aiobotocore/client.py", line 358, in _make_api_call
    raise error_class(parsed_response, operation_name)
botocore.exceptions.ClientError: An error occurred (RequestTimeTooSkewed) when calling the GetObject operation: The difference between the request time and the current time is too large.

The above exception was the direct cause of the following exception:

Traceback (most recent call last):
  File "/home/airflow/.local/lib/python3.7/site-packages/airflow/decorators/base.py", line 188, in execute
    return_value = super().execute(context)
  File "/home/airflow/.local/lib/python3.7/site-packages/airflow/operators/python.py", line 175, in execute
    return_value = self.execute_callable()
  File "/home/airflow/.local/lib/python3.7/site-packages/airflow/operators/python.py", line 193, in execute_callable
    return self.python_callable(*self.op_args, **self.op_kwargs)
  File "/opt/airflow/dags/trans_dag.py", line 34, in extract
    df = pd.read_csv(s3_path, storage_options=storage_options)
  File "/home/airflow/.local/lib/python3.7/site-packages/pandas/util/_decorators.py", line 311, in wrapper
    return func(*args, **kwargs)
  File "/home/airflow/.local/lib/python3.7/site-packages/pandas/io/parsers/readers.py", line 586, in read_csv
    return _read(filepath_or_buffer, kwds)
  File "/home/airflow/.local/lib/python3.7/site-packages/pandas/io/parsers/readers.py", line 482, in _read
    parser = TextFileReader(filepath_or_buffer, **kwds)
  File "/home/airflow/.local/lib/python3.7/site-packages/pandas/io/parsers/readers.py", line 811, in __init__
    self._engine = self._make_engine(self.engine)
  File "/home/airflow/.local/lib/python3.7/site-packages/pandas/io/parsers/readers.py", line 1040, in _make_engine
    return mapping[engine](self.f, **self.options)  # type: ignore[call-arg]
  File "/home/airflow/.local/lib/python3.7/site-packages/pandas/io/parsers/c_parser_wrapper.py", line 69, in __init__
    self._reader = parsers.TextReader(self.handles.handle, **kwds)
  File "pandas/_libs/parsers.pyx", line 542, in pandas._libs.parsers.TextReader.__cinit__
  File "pandas/_libs/parsers.pyx", line 642, in pandas._libs.parsers.TextReader._get_header
  File "pandas/_libs/parsers.pyx", line 843, in pandas._libs.parsers.TextReader._tokenize_rows
  File "pandas/_libs/parsers.pyx", line 1917, in pandas._libs.parsers.raise_parser_error
  File "/home/airflow/.local/lib/python3.7/site-packages/s3fs/core.py", line 2150, in _fetch_range
    req_kw=self.req_kw,
  File "/home/airflow/.local/lib/python3.7/site-packages/s3fs/core.py", line 2286, in _fetch_range
    return sync(fs.loop, _inner_fetch, fs, bucket, key, version_id, start, end, req_kw)
  File "/home/airflow/.local/lib/python3.7/site-packages/fsspec/asyn.py", line 99, in sync
    raise return_result
  File "/home/airflow/.local/lib/python3.7/site-packages/fsspec/asyn.py", line 54, in _runner
    result[0] = await coro
  File "/home/airflow/.local/lib/python3.7/site-packages/s3fs/core.py", line 2296, in _inner_fetch
    **req_kw,
  File "/home/airflow/.local/lib/python3.7/site-packages/s3fs/core.py", line 340, in _call_s3
    method, kwargs=additional_kwargs, retries=self.retries
  File "/home/airflow/.local/lib/python3.7/site-packages/s3fs/core.py", line 139, in _error_wrapper
    raise err
PermissionError: The difference between the request time and the current time is too large.
[2025-07-21T22:10:47.324+0000] {taskinstance.py:1406} INFO - Marking task as FAILED. dag_id=trans_dag_26, task_id=extract, execution_date=20250222T000000, start_date=20250721T183623, end_date=20250721T221047
[2025-07-21T22:10:47.566+0000] {standard_task_runner.py:105} ERROR - Failed to execute job 11029 for task extract (The difference between the request time and the current time is too large.; 85763)
[2025-07-21T22:10:47.868+0000] {local_task_job.py:164} INFO - Task exited with return code 1
[2025-07-21T22:10:48.387+0000] {local_task_job.py:273} INFO - 0 downstream tasks scheduled from follow-on schedule check
